<sdf version="1.4">
    <model name="drchubo">
        <link name="Body_Hip">
            <pose>0 0 0 0 -0 0</pose>
            <inertial>
                <pose>-0.0180731 7.04087e-07 -0.0324927 0 -0 0</pose>
                <mass>3.27532</mass>
                <inertia>
                    <ixx>0.0147101</ixx>
                    <ixy>-3.18965e-07</ixy>
                    <ixz>0.000204986</ixz>
                    <iyy>0.00491506</iyy>
                    <iyz>6.91609e-08</iyz>
                    <izz>0.0165337</izz>
                </inertia>
            </inertial>
            <collision name="Body_Hip_collision">
                <pose>0 0 0 0 -0 0</pose>
                <geometry>
                    <mesh>
                        <scale>1 1 1</scale>
                        <uri>model://drchubo/meshes/Body_Hip.stl</uri>
                    </mesh>
                </geometry>
            </collision>
            <visual name="Body_Hip_vis">
                <pose>0 0 0 0 -0 0</pose>
                <geometry>
                    <mesh>
                        <scale>1 1 1</scale>
                        <uri>model://drchubo/meshes/Body_Hip.stl</uri>
                    </mesh>
                </geometry>
            </visual>
        </link>
        <link name="Body_LHY">
            <pose>3.2347e-05 0.0885 -0.0235 0 -0 0</pose>
            <inertial>
                <pose>0.0136718 -4.98458e-08 -0.0799369 0 -0 0</pose>
                <mass>0.417518</mass>
                <inertia>
                    <ixx>0.000939663</ixx>
                    <ixy>-2.86257e-10</ixy>
                    <ixz>-0.00021151</ixz>
                    <iyy>0.00165967</iyy>
                    <iyz>-4.5223e-09</iyz>
                    <izz>0.000936466</izz>
                </inertia>
            </inertial>
            <collision name="Body_LHY_collision">
                <pose>0 0 0 0 -0 0</pose>
                <geometry>
                    <mesh>
                        <scale>1 1 1</scale>
                        <uri>model://drchubo/meshes/Body_LHY.stl</uri>
                    </mesh>
                </geometry>
            </collision>
            <visual name="Body_LHY_vis">
                <pose>0 0 0 0 -0 0</pose>
                <geometry>
                    <mesh>
                        <scale>1 1 1</scale>
                        <uri>model://drchubo/meshes/Body_LHY.stl</uri>
                    </mesh>
                </geometry>
            </visual>
        </link>
        <joint type="revolute" name="LHY">
            <child>Body_LHY</child>
            <parent>Body_Hip</parent>
            <axis>
                <xyz>0 0 1</xyz>
                <limit>
                    <lower>-1.92</lower>
                    <upper>1.92</upper>
                    <effort>100</effort>
                    <velocity>10</velocity>
                </limit>
                <dynamics />
            </axis>
        </joint>
        <link name="Body_LHR">
            <pose>3.2347e-05 0.0885 -0.16452 0 -0 0</pose>
            <inertial>
                <pose>0.0167408 0.00936839 -0.0157495 0 -0 0</pose>
                <mass>2.40945</mass>
                <inertia>
                    <ixx>0.00487692</ixx>
                    <ixy>-0.000379138</ixy>
                    <ixz>0.000631095</ixz>
                    <iyy>0.00495611</iyy>
                    <iyz>0.000648224</iyz>
                    <izz>0.00515523</izz>
                </inertia>
            </inertial>
            <collision name="Body_LHR_collision">
                <pose>0 0 0 0 -0 0</pose>
                <geometry>
                    <mesh>
                        <scale>1 1 1</scale>
                        <uri>model://drchubo/meshes/Body_LHR.stl</uri>
                    </mesh>
                </geometry>
            </collision>
            <visual name="Body_LHR_vis">
                <pose>0 0 0 0 -0 0</pose>
                <geometry>
                    <mesh>
                        <scale>1 1 1</scale>
                        <uri>model://drchubo/meshes/Body_LHR.stl</uri>
                    </mesh>
                </geometry>
            </visual>
        </link>
        <joint type="revolute" name="LHR">
            <child>Body_LHR</child>
            <parent>Body_LHY</parent>
            <axis>
                <xyz>1 0 0</xyz>
                <limit>
                    <lower>-0.52</lower>
                    <upper>0.52</upper>
                    <effort>100</effort>
                    <velocity>10</velocity>
                </limit>
                <dynamics />
            </axis>
        </joint>
        <link name="Body_LHP">
            <pose>3.2347e-05 0.0885 -0.16452 0 -0 0</pose>
            <inertial>
                <pose>0.0154169 0.0134376 -0.229569 0 -0 0</pose>
                <mass>2.37035</mass>
                <inertia>
                    <ixx>0.0313849</ixx>
                    <ixy>-0.000257888</ixy>
                    <ixz>0.000464519</ixz>
                    <iyy>0.029797</iyy>
                    <iyz>-7.62276e-05</iyz>
                    <izz>0.00544519</izz>
                </inertia>
            </inertial>
            <collision name="Body_LHP_collision">
                <pose>0 0 0 0 -0 0</pose>
                <geometry>
                    <mesh>
                        <scale>1 1 1</scale>
                        <uri>model://drchubo/meshes/Body_LHP.stl</uri>
                    </mesh>
                </geometry>
            </collision>
            <visual name="Body_LHP_vis">
                <pose>0 0 0 0 -0 0</pose>
                <geometry>
                    <mesh>
                        <scale>1 1 1</scale>
                        <uri>model://drchubo/meshes/Body_LHP.stl</uri>
                    </mesh>
                </geometry>
            </visual>
        </link>
        <joint type="revolute" name="LHP">
            <child>Body_LHP</child>
            <parent>Body_LHR</parent>
            <axis>
                <xyz>0 1 0</xyz>
                <limit>
                    <lower>-1.87</lower>
                    <upper>1.61</upper>
                    <effort>100</effort>
                    <velocity>10</velocity>
                </limit>
                <dynamics />
            </axis>
        </joint>
        <link name="Body_LKP">
            <pose>3.2347e-05 0.0885 -0.4946 0 -0 0</pose>
            <inertial>
                <pose>0.0168841 0.0107094 -0.153976 0 -0 0</pose>
                <mass>0.942742</mass>
                <inertia>
                    <ixx>0.0140835</ixx>
                    <ixy>3.80466e-08</ixy>
                    <ixz>-5.82548e-05</ixz>
                    <iyy>0.0125969</iyy>
                    <iyz>-0.000498009</iyz>
                    <izz>0.0025759</izz>
                </inertia>
            </inertial>
            <collision name="Body_LKP_collision">
                <pose>0 0 0 0 -0 0</pose>
                <geometry>
                    <mesh>
                        <scale>1 1 1</scale>
                        <uri>model://drchubo/meshes/Body_LKP.stl</uri>
                    </mesh>
                </geometry>
            </collision>
            <visual name="Body_LKP_vis">
                <pose>0 0 0 0 -0 0</pose>
                <geometry>
                    <mesh>
                        <scale>1 1 1</scale>
                        <uri>model://drchubo/meshes/Body_LKP.stl</uri>
                    </mesh>
                </geometry>
            </visual>
        </link>
        <joint type="revolute" name="LKP">
            <child>Body_LKP</child>
            <parent>Body_LHP</parent>
            <axis>
                <xyz>0 1 0</xyz>
                <limit>
                    <lower>-0.07</lower>
                    <upper>2.61</upper>
                    <effort>100</effort>
                    <velocity>10</velocity>
                </limit>
                <dynamics />
            </axis>
        </joint>
        <link name="Body_LAP">
            <pose>3.2347e-05 0.0885 -0.82455 0 -0 0</pose>
            <inertial>
                <pose>0.0130864 0.0193486 0.00939149 0 -0 0</pose>
                <mass>2.05748</mass>
                <inertia>
                    <ixx>0.00327242</ixx>
                    <ixy>-0.000200724</ixy>
                    <ixz>-0.000256256</ixz>
                    <iyy>0.0035313</iyy>
                    <iyz>-0.000293646</iyz>
                    <izz>0.00382005</izz>
                </inertia>
            </inertial>
            <collision name="Body_LAP_collision">
                <pose>0 0 0 0 -0 0</pose>
                <geometry>
                    <mesh>
                        <scale>1 1 1</scale>
                        <uri>model://drchubo/meshes/Body_LAP.stl</uri>
                    </mesh>
                </geometry>
            </collision>
            <visual name="Body_LAP_vis">
                <pose>0 0 0 0 -0 0</pose>
                <geometry>
                    <mesh>
                        <scale>1 1 1</scale>
                        <uri>model://drchubo/meshes/Body_LAP.stl</uri>
                    </mesh>
                </geometry>
            </visual>
        </link>
        <joint type="revolute" name="LAP">
            <child>Body_LAP</child>
            <parent>Body_LKP</parent>
            <axis>
                <xyz>0 1 0</xyz>
                <limit>
                    <lower>-1.64</lower>
                    <upper>1.69</upper>
                    <effort>100</effort>
                    <velocity>10</velocity>
                </limit>
                <dynamics />
            </axis>
        </joint>
        <link name="Body_LAR">
            <pose>3.2347e-05 0.0985 -0.82455 0 -0 0</pose>
            <inertial>
                <pose>0.00490632 0.00313698 -0.0777633 0 -0 0</pose>
                <mass>1.15884</mass>
                <inertia>
                    <ixx>0.00419229</ixx>
                    <ixy>-8.48649e-06</ixy>
                    <ixz>0.000234343</ixz>
                    <iyy>0.00746857</iyy>
                    <iyz>-3.69091e-05</iyz>
                    <izz>0.00666595</izz>
                </inertia>
            </inertial>
            <collision name="Body_LAR_collision">
                <pose>0 0 0 0 -0 0</pose>
                <geometry>
                    <mesh>
                        <scale>1 1 1</scale>
                        <uri>model://drchubo/meshes/Body_LAR.stl</uri>
                    </mesh>
                </geometry>
            </collision>
            <visual name="Body_LAR_vis">
                <pose>0 0 0 0 -0 0</pose>
                <geometry>
                    <mesh>
                        <scale>1 1 1</scale>
                        <uri>model://drchubo/meshes/Body_LAR.stl</uri>
                    </mesh>
                </geometry>
            </visual>
        </link>
        <joint type="revolute" name="LAR">
            <child>Body_LAR</child>
            <parent>Body_LAP</parent>
            <axis>
                <xyz>1 0 0</xyz>
                <limit>
                    <lower>-0.44</lower>
                    <upper>0.44</upper>
                    <effort>100</effort>
                    <velocity>10</velocity>
                </limit>
                <dynamics />
            </axis>
        </joint>
        <link name="Body_RHY">
            <pose>3.2347e-05 -0.0885 -0.0235 0 -0 0</pose>
            <inertial>
                <pose>0.0136718 4.98458e-08 -0.0799369 0 -0 0</pose>
                <mass>0.417518</mass>
                <inertia>
                    <ixx>0.000939663</ixx>
                    <ixy>2.86257e-10</ixy>
                    <ixz>-0.00021151</ixz>
                    <iyy>0.00165967</iyy>
                    <iyz>4.5223e-09</iyz>
                    <izz>0.000936466</izz>
                </inertia>
            </inertial>
            <collision name="Body_RHY_collision">
                <pose>0 -0 0 0 -0 0</pose>
                <geometry>
                    <mesh>
                        <scale>1 1 1</scale>
                        <uri>model://drchubo/meshes/Body_RHY.stl</uri>
                    </mesh>
                </geometry>
            </collision>
            <visual name="Body_RHY_vis">
                <pose>0 -0 0 0 -0 0</pose>
                <geometry>
                    <mesh>
                        <scale>1 1 1</scale>
                        <uri>model://drchubo/meshes/Body_RHY.stl</uri>
                    </mesh>
                </geometry>
            </visual>
        </link>
        <joint type="revolute" name="RHY">
            <child>Body_RHY</child>
            <parent>Body_Hip</parent>
            <axis>
                <xyz>0 0 1</xyz>
                <limit>
                    <lower>-1.92</lower>
                    <upper>1.92</upper>
                    <effort>100</effort>
                    <velocity>10</velocity>
                </limit>
                <dynamics />
            </axis>
        </joint>
        <link name="Body_RHR">
            <pose>3.2347e-05 -0.0885 -0.16452 0 -0 0</pose>
            <inertial>
                <pose>0.0167408 -0.00936839 -0.0157495 0 -0 0</pose>
                <mass>2.40945</mass>
                <inertia>
                    <ixx>0.00487692</ixx>
                    <ixy>0.000379138</ixy>
                    <ixz>0.000631095</ixz>
                    <iyy>0.00495611</iyy>
                    <iyz>-0.000648224</iyz>
                    <izz>0.00515523</izz>
                </inertia>
            </inertial>
            <collision name="Body_RHR_collision">
                <pose>0 -0 0 0 -0 0</pose>
                <geometry>
                    <mesh>
                        <scale>1 1 1</scale>
                        <uri>model://drchubo/meshes/Body_RHR.stl</uri>
                    </mesh>
                </geometry>
            </collision>
            <visual name="Body_RHR_vis">
                <pose>0 -0 0 0 -0 0</pose>
                <geometry>
                    <mesh>
                        <scale>1 1 1</scale>
                        <uri>model://drchubo/meshes/Body_RHR.stl</uri>
                    </mesh>
                </geometry>
            </visual>
        </link>
        <joint type="revolute" name="RHR">
            <child>Body_RHR</child>
            <parent>Body_RHY</parent>
            <axis>
                <xyz>1 0 0</xyz>
                <limit>
                    <lower>-0.52</lower>
                    <upper>0.52</upper>
                    <effort>100</effort>
                    <velocity>10</velocity>
                </limit>
                <dynamics />
            </axis>
        </joint>
        <link name="Body_RHP">
            <pose>3.2347e-05 -0.0885 -0.16452 0 -0 0</pose>
            <inertial>
                <pose>0.0154169 -0.0134376 -0.229569 0 -0 0</pose>
                <mass>2.37035</mass>
                <inertia>
                    <ixx>0.0313849</ixx>
                    <ixy>0.000257888</ixy>
                    <ixz>0.000464519</ixz>
                    <iyy>0.029797</iyy>
                    <iyz>7.62276e-05</iyz>
                    <izz>0.00544519</izz>
                </inertia>
            </inertial>
            <collision name="Body_RHP_collision">
                <pose>0 -0 0 0 -0 0</pose>
                <geometry>
                    <mesh>
                        <scale>1 1 1</scale>
                        <uri>model://drchubo/meshes/Body_RHP.stl</uri>
                    </mesh>
                </geometry>
            </collision>
            <visual name="Body_RHP_vis">
                <pose>0 -0 0 0 -0 0</pose>
                <geometry>
                    <mesh>
                        <scale>1 1 1</scale>
                        <uri>model://drchubo/meshes/Body_RHP.stl</uri>
                    </mesh>
                </geometry>
            </visual>
        </link>
        <joint type="revolute" name="RHP">
            <child>Body_RHP</child>
            <parent>Body_RHR</parent>
            <axis>
                <xyz>0 1 0</xyz>
                <limit>
                    <lower>-1.87</lower>
                    <upper>1.61</upper>
                    <effort>100</effort>
                    <velocity>10</velocity>
                </limit>
                <dynamics />
            </axis>
        </joint>
        <link name="Body_RKP">
            <pose>3.2347e-05 -0.0885 -0.4946 0 -0 0</pose>
            <inertial>
                <pose>0.0168841 -0.0107094 -0.153976 0 -0 0</pose>
                <mass>0.942742</mass>
                <inertia>
                    <ixx>0.0140835</ixx>
                    <ixy>-3.80466e-08</ixy>
                    <ixz>-5.82548e-05</ixz>
                    <iyy>0.0125969</iyy>
                    <iyz>0.000498009</iyz>
                    <izz>0.0025759</izz>
                </inertia>
            </inertial>
            <collision name="Body_RKP_collision">
                <pose>0 -0 0 0 -0 0</pose>
                <geometry>
                    <mesh>
                        <scale>1 1 1</scale>
                        <uri>model://drchubo/meshes/Body_RKP.stl</uri>
                    </mesh>
                </geometry>
            </collision>
            <visual name="Body_RKP_vis">
                <pose>0 -0 0 0 -0 0</pose>
                <geometry>
                    <mesh>
                        <scale>1 1 1</scale>
                        <uri>model://drchubo/meshes/Body_RKP.stl</uri>
                    </mesh>
                </geometry>
            </visual>
        </link>
        <joint type="revolute" name="RKP">
            <child>Body_RKP</child>
            <parent>Body_RHP</parent>
            <axis>
                <xyz>0 1 0</xyz>
                <limit>
                    <lower>-0.07</lower>
                    <upper>2.61</upper>
                    <effort>100</effort>
                    <velocity>10</velocity>
                </limit>
                <dynamics />
            </axis>
        </joint>
        <link name="Body_RAP">
            <pose>3.2347e-05 -0.0885 -0.82455 0 -0 0</pose>
            <inertial>
                <pose>0.0130864 -0.0193486 0.00939149 0 -0 0</pose>
                <mass>2.05748</mass>
                <inertia>
                    <ixx>0.00327242</ixx>
                    <ixy>0.000200724</ixy>
                    <ixz>-0.000256256</ixz>
                    <iyy>0.0035313</iyy>
                    <iyz>0.000293646</iyz>
                    <izz>0.00382005</izz>
                </inertia>
            </inertial>
            <collision name="Body_RAP_collision">
                <pose>0 -0 0 0 -0 0</pose>
                <geometry>
                    <mesh>
                        <scale>1 1 1</scale>
                        <uri>model://drchubo/meshes/Body_RAP.stl</uri>
                    </mesh>
                </geometry>
            </collision>
            <visual name="Body_RAP_vis">
                <pose>0 -0 0 0 -0 0</pose>
                <geometry>
                    <mesh>
                        <scale>1 1 1</scale>
                        <uri>model://drchubo/meshes/Body_RAP.stl</uri>
                    </mesh>
                </geometry>
            </visual>
        </link>
        <joint type="revolute" name="RAP">
            <child>Body_RAP</child>
            <parent>Body_RKP</parent>
            <axis>
                <xyz>0 1 0</xyz>
                <limit>
                    <lower>-1.64</lower>
                    <upper>1.69</upper>
                    <effort>100</effort>
                    <velocity>10</velocity>
                </limit>
                <dynamics />
            </axis>
        </joint>
        <link name="Body_RAR">
            <pose>3.2347e-05 -0.0985 -0.82455 0 -0 0</pose>
            <inertial>
                <pose>0.00490632 -0.00313698 -0.0777633 0 -0 0</pose>
                <mass>1.15884</mass>
                <inertia>
                    <ixx>0.00419229</ixx>
                    <ixy>8.48649e-06</ixy>
                    <ixz>0.000234343</ixz>
                    <iyy>0.00746857</iyy>
                    <iyz>3.69091e-05</iyz>
                    <izz>0.00666595</izz>
                </inertia>
            </inertial>
            <collision name="Body_RAR_collision">
                <pose>0 -0 0 0 -0 0</pose>
                <geometry>
                    <mesh>
                        <scale>1 1 1</scale>
                        <uri>model://drchubo/meshes/Body_RAR.stl</uri>
                    </mesh>
                </geometry>
            </collision>
            <visual name="Body_RAR_vis">
                <pose>0 -0 0 0 -0 0</pose>
                <geometry>
                    <mesh>
                        <scale>1 1 1</scale>
                        <uri>model://drchubo/meshes/Body_RAR.stl</uri>
                    </mesh>
                </geometry>
            </visual>
        </link>
        <joint type="revolute" name="RAR">
            <child>Body_RAR</child>
            <parent>Body_RAP</parent>
            <axis>
                <xyz>1 0 0</xyz>
                <limit>
                    <lower>-0.44</lower>
                    <upper>0.44</upper>
                    <effort>100</effort>
                    <velocity>10</velocity>
                </limit>
                <dynamics />
            </axis>
        </joint>
        <link name="Body_Torso">
            <pose>0 0 0 0 -0 0</pose>
            <inertial>
                <pose>-0.0238238 -0.000303665 0.178273 0 -0 0</pose>
                <mass>1.07803</mass>
                <inertia>
                    <ixx>0.0175077</ixx>
                    <ixy>-8.66965e-06</ixy>
                    <ixz>-0.001057</ixz>
                    <iyy>0.0101293</iyy>
                    <iyz>-6.3405e-06</iyz>
                    <izz>0.0117063</izz>
                </inertia>
            </inertial>
            <collision name="Body_Torso_collision">
                <pose>0 0 0 0 -0 0</pose>
                <geometry>
                    <mesh>
                        <scale>1 1 1</scale>
                        <uri>model://drchubo/meshes/Body_Torso.stl</uri>
                    </mesh>
                </geometry>
            </collision>
            <visual name="Body_Torso_vis">
                <pose>0 0 0 0 -0 0</pose>
                <geometry>
                    <mesh>
                        <scale>1 1 1</scale>
                        <uri>model://drchubo/meshes/Body_Torso.stl</uri>
                    </mesh>
                </geometry>
            </visual>
        </link>
        <joint type="revolute" name="TSY">
            <child>Body_Torso</child>
            <parent>Body_Hip</parent>
            <axis>
                <xyz>0 0 1</xyz>
                <limit>
                    <lower>-1.57</lower>
                    <upper>1.57</upper>
                    <effort>100</effort>
                    <velocity>10</velocity>
                </limit>
                <dynamics />
            </axis>
        </joint>
        <link name="Body_LSP">
            <pose>0.00152455 0.125013 0.1971 0 -0 0</pose>
            <inertial>
                <pose>0.0117256 0.0467776 0.000222706 0 -0 0</pose>
                <mass>0.632586</mass>
                <inertia>
                    <ixx>0.00111111</ixx>
                    <ixy>0.000259133</ixy>
                    <ixz>-1.56634e-06</ixz>
                    <iyy>0.00102934</iyy>
                    <iyz>-4.71727e-06</iyz>
                    <izz>0.00154859</izz>
                </inertia>
            </inertial>
            <collision name="Body_LSP_collision">
                <pose>0 0 0 0 -0 0</pose>
                <geometry>
                    <mesh>
                        <scale>1 1 1</scale>
                        <uri>model://drchubo/meshes/Body_LSP.stl</uri>
                    </mesh>
                </geometry>
            </collision>
            <visual name="Body_LSP_vis">
                <pose>0 0 0 0 -0 0</pose>
                <geometry>
                    <mesh>
                        <scale>1 1 1</scale>
                        <uri>model://drchubo/meshes/Body_LSP.stl</uri>
                    </mesh>
                </geometry>
            </visual>
        </link>
        <joint type="revolute" name="LSP">
            <child>Body_LSP</child>
            <parent>Body_Torso</parent>
            <axis>
                <xyz>0 1 0</xyz>
                <limit>
                    <lower>-3.14</lower>
                    <upper>3.14</upper>
                    <effort>100</effort>
                    <velocity>10</velocity>
                </limit>
                <dynamics />
            </axis>
        </joint>
        <link name="Body_LSR">
            <pose>0.00152455 0.208513 0.1971 0 -0 0</pose>
            <inertial>
                <pose>-0.000145637 0.000254338 -0.0220669 0 -0 0</pose>
                <mass>0.333137</mass>
                <inertia>
                    <ixx>0.000352</ixx>
                    <ixy>1.27542e-08</ixy>
                    <ixz>4.69391e-06</ixz>
                    <iyy>0.000402775</iyy>
                    <iyz>-1.05629e-06</iyz>
                    <izz>0.000295328</izz>
                </inertia>
            </inertial>
            <collision name="Body_LSR_collision">
                <pose>0 0 0 0 -0 0</pose>
                <geometry>
                    <mesh>
                        <scale>1 1 1</scale>
                        <uri>model://drchubo/meshes/Body_LSR.stl</uri>
                    </mesh>
                </geometry>
            </collision>
            <visual name="Body_LSR_vis">
                <pose>0 0 0 0 -0 0</pose>
                <geometry>
                    <mesh>
                        <scale>1 1 1</scale>
                        <uri>model://drchubo/meshes/Body_LSR.stl</uri>
                    </mesh>
                </geometry>
            </visual>
        </link>
        <joint type="revolute" name="LSR">
            <child>Body_LSR</child>
            <parent>Body_LSP</parent>
            <axis>
                <xyz>1 0 0</xyz>
                <limit>
                    <lower>-0.262</lower>
                    <upper>3.14</upper>
                    <effort>100</effort>
                    <velocity>10</velocity>
                </limit>
                <dynamics />
            </axis>
        </joint>
        <link name="Body_LSY">
            <pose>0.00152455 0.208513 0.1394 0 -0 0</pose>
            <inertial>
                <pose>0.0105832 0.00193701 -0.172649 0 -0 0</pose>
                <mass>0.730103</mass>
                <inertia>
                    <ixx>0.00482614</ixx>
                    <ixy>9.299e-06</ixy>
                    <ixz>-0.000535314</ixz>
                    <iyy>0.00476186</iyy>
                    <iyz>-7.76901e-05</iyz>
                    <izz>0.000629421</izz>
                </inertia>
            </inertial>
            <collision name="Body_LSY_collision">
                <pose>0 0 0 0 -0 0</pose>
                <geometry>
                    <mesh>
                        <scale>1 1 1</scale>
                        <uri>model://drchubo/meshes/Body_LSY.stl</uri>
                    </mesh>
                </geometry>
            </collision>
            <visual name="Body_LSY_vis">
                <pose>0 0 0 0 -0 0</pose>
                <geometry>
                    <mesh>
                        <scale>1 1 1</scale>
                        <uri>model://drchubo/meshes/Body_LSY.stl</uri>
                    </mesh>
                </geometry>
            </visual>
        </link>
        <joint type="revolute" name="LSY">
            <child>Body_LSY</child>
            <parent>Body_LSR</parent>
            <axis>
                <xyz>0 0 1</xyz>
                <limit>
                    <lower>-2</lower>
                    <upper>3.14</upper>
                    <effort>100</effort>
                    <velocity>10</velocity>
                </limit>
                <dynamics />
            </axis>
        </joint>
        <link name="Body_LEP">
            <pose>0.0315245 0.208513 -0.1036 0 -0 0</pose>
            <inertial>
                <pose>-0.0226986 -0.00410742 -0.0393891 0 -0 0</pose>
                <mass>0.186909</mass>
                <inertia>
                    <ixx>0.000270994</ixx>
                    <ixy>5.10319e-06</ixy>
                    <ixz>4.85529e-05</ixz>
                    <iyy>0.000232506</iyy>
                    <iyz>-6.66148e-06</iyz>
                    <izz>0.000178997</izz>
                </inertia>
            </inertial>
            <collision name="Body_LEP_collision">
                <pose>0 0 0 0 -0 0</pose>
                <geometry>
                    <mesh>
                        <scale>1 1 1</scale>
                        <uri>model://drchubo/meshes/Body_LEP.stl</uri>
                    </mesh>
                </geometry>
            </collision>
            <visual name="Body_LEP_vis">
                <pose>0 0 0 0 -0 0</pose>
                <geometry>
                    <mesh>
                        <scale>1 1 1</scale>
                        <uri>model://drchubo/meshes/Body_LEP.stl</uri>
                    </mesh>
                </geometry>
            </visual>
        </link>
        <joint type="revolute" name="LEP">
            <child>Body_LEP</child>
            <parent>Body_LSY</parent>
            <axis>
                <xyz>0 1 0</xyz>
                <limit>
                    <lower>-2.96</lower>
                    <upper>0</upper>
                    <effort>100</effort>
                    <velocity>10</velocity>
                </limit>
                <dynamics />
            </axis>
        </joint>
        <link name="Body_LWY">
            <pose>0.00152455 0.208513 -0.2196 0 -0 0</pose>
            <inertial>
                <pose>4.52566e-05 0.063616 -0.095905 0 -0 0</pose>
                <mass>0.434231</mass>
                <inertia>
                    <ixx>0.00354953</ixx>
                    <ixy>-6.67149e-07</ixy>
                    <ixz>2.34545e-06</ixz>
                    <iyy>0.00320829</iyy>
                    <iyz>-0.000697731</iyz>
                    <izz>0.000522002</izz>
                </inertia>
            </inertial>
            <collision name="Body_LWY_collision">
                <pose>0 0 0 0 -0 0</pose>
                <geometry>
                    <mesh>
                        <scale>1 1 1</scale>
                        <uri>model://drchubo/meshes/Body_LWY.stl</uri>
                    </mesh>
                </geometry>
            </collision>
            <visual name="Body_LWY_vis">
                <pose>0 0 0 0 -0 0</pose>
                <geometry>
                    <mesh>
                        <scale>1 1 1</scale>
                        <uri>model://drchubo/meshes/Body_LWY.stl</uri>
                    </mesh>
                </geometry>
            </visual>
        </link>
        <joint type="revolute" name="LWY">
            <child>Body_LWY</child>
            <parent>Body_LEP</parent>
            <axis>
                <xyz>0 0 1</xyz>
                <limit>
                    <lower>-3.14</lower>
                    <upper>3.14</upper>
                    <effort>100</effort>
                    <velocity>10</velocity>
                </limit>
                <dynamics />
            </axis>
        </joint>
        <link name="Body_LWP">
            <pose>0.00152455 0.208513 -0.40431 0 -1.5708 0</pose>
            <inertial>
                <pose>-9.30859e-05 0.0135063 0.0305015 0 -0 0</pose>
                <mass>0.219017</mass>
                <inertia>
                    <ixx>0.000536599</ixx>
                    <ixy>-1.09318e-06</ixy>
                    <ixz>6.19834e-07</ixz>
                    <iyy>0.000445109</iyy>
                    <iyz>-8.97811e-05</iyz>
                    <izz>0.000148768</izz>
                </inertia>
            </inertial>
            <collision name="Body_LWP_collision">
                <pose>0 0 0 0 -0 0</pose>
                <geometry>
                    <mesh>
                        <scale>1 1 1</scale>
                        <uri>model://drchubo/meshes/Body_LWP.stl</uri>
                    </mesh>
                </geometry>
            </collision>
            <visual name="Body_LWP_vis">
                <pose>0 0 0 0 -0 0</pose>
                <geometry>
                    <mesh>
                        <scale>1 1 1</scale>
                        <uri>model://drchubo/meshes/Body_LWP.stl</uri>
                    </mesh>
                </geometry>
            </visual>
        </link>
        <joint type="revolute" name="LWP">
            <child>Body_LWP</child>
            <parent>Body_LWY</parent>
            <axis>
                <xyz>0 1 0</xyz>
                <limit>
                    <lower>-3.14</lower>
                    <upper>3.14</upper>
                    <effort>100</effort>
                    <velocity>10</velocity>
                </limit>
                <dynamics />
            </axis>
        </joint>
        <link name="Body_LWR">
            <pose>0.0130245 0.208513 -0.40431 0 -1.5708 0</pose>
            <inertial>
                <pose>0.000360815 -0.00215836 -0.0655917 0 -0 0</pose>
                <mass>0.269108</mass>
                <inertia>
                    <ixx>0.00115611</ixx>
                    <ixy>5.43644e-07</ixy>
                    <ixz>-8.57165e-07</ixz>
                    <iyy>0.00110454</iyy>
                    <iyz>5.88366e-06</iyz>
                    <izz>0.000216819</izz>
                </inertia>
            </inertial>
            <collision name="Body_LWR_collision">
                <pose>0 0 0 0 -0 0</pose>
                <geometry>
                    <mesh>
                        <scale>1 1 1</scale>
                        <uri>model://drchubo/meshes/Body_LWR.stl</uri>
                    </mesh>
                </geometry>
            </collision>
            <visual name="Body_LWR_vis">
                <pose>0 0 0 0 -0 0</pose>
                <geometry>
                    <mesh>
                        <scale>1 1 1</scale>
                        <uri>model://drchubo/meshes/Body_LWR.stl</uri>
                    </mesh>
                </geometry>
            </visual>
        </link>
        <joint type="revolute" name="LWR">
            <child>Body_LWR</child>
            <parent>Body_LWP</parent>
            <axis>
                <xyz>-1 0 2.22045e-16</xyz>
                <limit>
                    <lower>-3.14</lower>
                    <upper>3.14</upper>
                    <effort>100</effort>
                    <velocity>10</velocity>
                </limit>
                <dynamics />
            </axis>
        </joint>
        <link name="Body_LF1">
            <pose>0.0885245 0.192043 -0.38131 0 -1.47552 0</pose>
            <inertial>
                <pose>0.0408954 -0.0103258 -0.00671454 0 -0 0</pose>
                <mass>0.0548659</mass>
                <inertia>
                    <ixx>1.25606e-05</ixx>
                    <ixy>1.93836e-07</ixy>
                    <ixz>-1.55634e-05</ixz>
                    <iyy>5.80752e-05</iyy>
                    <iyz>-1.14011e-07</iyz>
                    <izz>4.92973e-05</izz>
                </inertia>
            </inertial>
            <collision name="Body_LF1_collision">
                <pose>0 0 0 0 -0 0</pose>
                <geometry>
                    <mesh>
                        <scale>1 1 1</scale>
                        <uri>model://drchubo/meshes/Body_LF1.stl</uri>
                    </mesh>
                </geometry>
            </collision>
            <visual name="Body_LF1_vis">
                <pose>0 0 0 0 -0 0</pose>
                <geometry>
                    <mesh>
                        <scale>1 1 1</scale>
                        <uri>model://drchubo/meshes/Body_LF1.stl</uri>
                    </mesh>
                </geometry>
            </visual>
        </link>
        <joint type="revolute" name="LF1">
            <child>Body_LF1</child>
            <parent>Body_LWR</parent>
            <axis>
                <xyz>0 1 0</xyz>
                <limit>
                    <lower>-0.1</lower>
                    <upper>1.1</upper>
                    <effort>100</effort>
                    <velocity>10</velocity>
                </limit>
                <dynamics />
            </axis>
        </joint>
        <link name="Body_LF2">
            <pose>0.0885245 0.224984 -0.38131 0 -1.47552 0</pose>
            <inertial>
                <pose>0.0408954 0.0107335 -0.00671454 0 -0 0</pose>
                <mass>0.0548659</mass>
                <inertia>
                    <ixx>1.25606e-05</ixx>
                    <ixy>1.93836e-07</ixy>
                    <ixz>-1.55634e-05</ixz>
                    <iyy>5.80752e-05</iyy>
                    <iyz>-1.14011e-07</iyz>
                    <izz>4.92973e-05</izz>
                </inertia>
            </inertial>
            <collision name="Body_LF2_collision">
                <pose>0 0 0 0 -0 0</pose>
                <geometry>
                    <mesh>
                        <scale>1 1 1</scale>
                        <uri>model://drchubo/meshes/Body_LF2.stl</uri>
                    </mesh>
                </geometry>
            </collision>
            <visual name="Body_LF2_vis">
                <pose>0 0 0 0 -0 0</pose>
                <geometry>
                    <mesh>
                        <scale>1 1 1</scale>
                        <uri>model://drchubo/meshes/Body_LF2.stl</uri>
                    </mesh>
                </geometry>
            </visual>
        </link>
        <joint type="revolute" name="LF2">
            <child>Body_LF2</child>
            <parent>Body_LWR</parent>
            <axis>
                <xyz>0 1 0</xyz>
                <limit>
                    <lower>-0.1</lower>
                    <upper>1.1</upper>
                    <effort>100</effort>
                    <velocity>10</velocity>
                </limit>
                <dynamics />
            </axis>
        </joint>
        <link name="Body_LF3">
            <pose>0.0885245 0.208513 -0.42731 3.14159 1.47552 -3.38109e-14</pose>
            <inertial>
                <pose>0.0408954 0.000203817 -0.00671454 0 -0 0</pose>
                <mass>0.0548659</mass>
                <inertia>
                    <ixx>1.25606e-05</ixx>
                    <ixy>1.93836e-07</ixy>
                    <ixz>-1.55634e-05</ixz>
                    <iyy>5.80752e-05</iyy>
                    <iyz>-1.14011e-07</iyz>
                    <izz>4.92973e-05</izz>
                </inertia>
            </inertial>
            <collision name="Body_LF3_collision">
                <pose>0 0 0 0 -0 0</pose>
                <geometry>
                    <mesh>
                        <scale>1 1 1</scale>
                        <uri>model://drchubo/meshes/Body_LF3.stl</uri>
                    </mesh>
                </geometry>
            </collision>
            <visual name="Body_LF3_vis">
                <pose>0 0 0 0 -0 0</pose>
                <geometry>
                    <mesh>
                        <scale>1 1 1</scale>
                        <uri>model://drchubo/meshes/Body_LF3.stl</uri>
                    </mesh>
                </geometry>
            </visual>
        </link>
        <joint type="revolute" name="LF3">
            <child>Body_LF3</child>
            <parent>Body_LWR</parent>
            <axis>
                <xyz>4.93038e-31 -1 3.23109e-15</xyz>
                <limit>
                    <lower>-0.1</lower>
                    <upper>1.1</upper>
                    <effort>100</effort>
                    <velocity>10</velocity>
                </limit>
                <dynamics />
            </axis>
        </joint>
        <link name="Body_NKY">
            <pose>3.2347e-05 0 0.2561 0 -0 0</pose>
            <inertial>
                <pose>-0.0139148 -0.00578984 0.0406691 0 -0 0</pose>
                <mass>0.239812</mass>
                <inertia>
                    <ixx>0.000131294</ixx>
                    <ixy>-2.10022e-05</ixy>
                    <ixz>-1.78409e-05</ixz>
                    <iyy>0.000112106</iyy>
                    <iyz>-7.83573e-06</iyz>
                    <izz>0.000131014</izz>
                </inertia>
            </inertial>
            <collision name="Body_NKY_collision">
                <pose>0 0 0 0 -0 0</pose>
                <geometry>
                    <mesh>
                        <scale>1 1 1</scale>
                        <uri>model://drchubo/meshes/Body_NKY.stl</uri>
                    </mesh>
                </geometry>
            </collision>
            <visual name="Body_NKY_vis">
                <pose>0 0 0 0 -0 0</pose>
                <geometry>
                    <mesh>
                        <scale>1 1 1</scale>
                        <uri>model://drchubo/meshes/Body_NKY.stl</uri>
                    </mesh>
                </geometry>
            </visual>
        </link>
        <joint type="revolute" name="NKY">
            <child>Body_NKY</child>
            <parent>Body_Torso</parent>
            <axis>
                <xyz>0 0 1</xyz>
                <limit>
                    <lower>-1.57</lower>
                    <upper>1.57</upper>
                    <effort>100</effort>
                    <velocity>10</velocity>
                </limit>
                <dynamics />
            </axis>
        </joint>
        <link name="Body_NKP">
            <pose>3.2347e-05 0 0.3061 0 0 -3.14159</pose>
            <inertial>
                <pose>0.00266669 -0.00347539 0.0631854 0 -0 0</pose>
                <mass>0.294512</mass>
                <inertia>
                    <ixx>0.000655062</ixx>
                    <ixy>-5.2494e-07</ixy>
                    <ixz>1.40514e-06</ixz>
                    <iyy>0.000132805</iyy>
                    <iyz>-1.47486e-05</iyz>
                    <izz>0.000621667</izz>
                </inertia>
            </inertial>
            <collision name="Body_NKP_collision">
                <pose>0 0 0 0 -0 0</pose>
                <geometry>
                    <mesh>
                        <scale>1 1 1</scale>
                        <uri>model://drchubo/meshes/Body_NKP.stl</uri>
                    </mesh>
                </geometry>
            </collision>
            <visual name="Body_NKP_vis">
                <pose>0 0 0 0 -0 0</pose>
                <geometry>
                    <mesh>
                        <scale>1 1 1</scale>
                        <uri>model://drchubo/meshes/Body_NKP.stl</uri>
                    </mesh>
                </geometry>
            </visual>
        </link>
        <joint type="revolute" name="NKP">
            <child>Body_NKP</child>
            <parent>Body_NKY</parent>
            <axis>
                <xyz>3.23109e-15 -1 0</xyz>
                <limit>
                    <lower>-1.57</lower>
                    <upper>1.57</upper>
                    <effort>100</effort>
                    <velocity>10</velocity>
                </limit>
                <dynamics />
            </axis>
        </joint>
        <link name="Body_RSP">
            <pose>0.00152455 -0.125013 0.1971 0 -0 0</pose>
            <inertial>
                <pose>0.0117256 -0.0467776 0.000222706 0 -0 0</pose>
                <mass>0.632586</mass>
                <inertia>
                    <ixx>0.00111111</ixx>
                    <ixy>-0.000259133</ixy>
                    <ixz>-1.56634e-06</ixz>
                    <iyy>0.00102934</iyy>
                    <iyz>4.71727e-06</iyz>
                    <izz>0.00154859</izz>
                </inertia>
            </inertial>
            <collision name="Body_RSP_collision">
                <pose>0 -0 0 0 -0 0</pose>
                <geometry>
                    <mesh>
                        <scale>1 1 1</scale>
                        <uri>model://drchubo/meshes/Body_RSP.stl</uri>
                    </mesh>
                </geometry>
            </collision>
            <visual name="Body_RSP_vis">
                <pose>0 -0 0 0 -0 0</pose>
                <geometry>
                    <mesh>
                        <scale>1 1 1</scale>
                        <uri>model://drchubo/meshes/Body_RSP.stl</uri>
                    </mesh>
                </geometry>
            </visual>
        </link>
        <joint type="revolute" name="RSP">
            <child>Body_RSP</child>
            <parent>Body_Torso</parent>
            <axis>
                <xyz>0 1 0</xyz>
                <limit>
                    <lower>-3.14</lower>
                    <upper>3.14</upper>
                    <effort>100</effort>
                    <velocity>10</velocity>
                </limit>
                <dynamics />
            </axis>
        </joint>
        <link name="Body_RSR">
            <pose>0.00152455 -0.208513 0.1971 0 -0 0</pose>
            <inertial>
                <pose>-0.000145637 -0.000254338 -0.0220669 0 -0 0</pose>
                <mass>0.333137</mass>
                <inertia>
                    <ixx>0.000352</ixx>
                    <ixy>-1.27542e-08</ixy>
                    <ixz>4.69391e-06</ixz>
                    <iyy>0.000402775</iyy>
                    <iyz>1.05629e-06</iyz>
                    <izz>0.000295328</izz>
                </inertia>
            </inertial>
            <collision name="Body_RSR_collision">
                <pose>0 -0 0 0 -0 0</pose>
                <geometry>
                    <mesh>
                        <scale>1 1 1</scale>
                        <uri>model://drchubo/meshes/Body_RSR.stl</uri>
                    </mesh>
                </geometry>
            </collision>
            <visual name="Body_RSR_vis">
                <pose>0 -0 0 0 -0 0</pose>
                <geometry>
                    <mesh>
                        <scale>1 1 1</scale>
                        <uri>model://drchubo/meshes/Body_RSR.stl</uri>
                    </mesh>
                </geometry>
            </visual>
        </link>
        <joint type="revolute" name="RSR">
            <child>Body_RSR</child>
            <parent>Body_RSP</parent>
            <axis>
                <xyz>1 0 0</xyz>
                <limit>
                    <lower>-3.14</lower>
                    <upper>0.262</upper>
                    <effort>100</effort>
                    <velocity>10</velocity>
                </limit>
                <dynamics />
            </axis>
        </joint>
        <link name="Body_RSY">
            <pose>0.00152455 -0.208513 0.1394 0 -0 0</pose>
            <inertial>
                <pose>0.0105832 -0.00193701 -0.172649 0 -0 0</pose>
                <mass>0.730103</mass>
                <inertia>
                    <ixx>0.00482614</ixx>
                    <ixy>-9.299e-06</ixy>
                    <ixz>-0.000535314</ixz>
                    <iyy>0.00476186</iyy>
                    <iyz>7.76901e-05</iyz>
                    <izz>0.000629421</izz>
                </inertia>
            </inertial>
            <collision name="Body_RSY_collision">
                <pose>0 -0 0 0 -0 0</pose>
                <geometry>
                    <mesh>
                        <scale>1 1 1</scale>
                        <uri>model://drchubo/meshes/Body_RSY.stl</uri>
                    </mesh>
                </geometry>
            </collision>
            <visual name="Body_RSY_vis">
                <pose>0 -0 0 0 -0 0</pose>
                <geometry>
                    <mesh>
                        <scale>1 1 1</scale>
                        <uri>model://drchubo/meshes/Body_RSY.stl</uri>
                    </mesh>
                </geometry>
            </visual>
        </link>
        <joint type="revolute" name="RSY">
            <child>Body_RSY</child>
            <parent>Body_RSR</parent>
            <axis>
                <xyz>0 0 1</xyz>
                <limit>
                    <lower>-3.14</lower>
                    <upper>2</upper>
                    <effort>100</effort>
                    <velocity>10</velocity>
                </limit>
                <dynamics />
            </axis>
        </joint>
        <link name="Body_REP">
            <pose>0.0315245 -0.208513 -0.1036 0 -0 0</pose>
            <inertial>
                <pose>-0.0226986 0.00410742 -0.0393891 0 -0 0</pose>
                <mass>0.186909</mass>
                <inertia>
                    <ixx>0.000270994</ixx>
                    <ixy>-5.10319e-06</ixy>
                    <ixz>4.85529e-05</ixz>
                    <iyy>0.000232506</iyy>
                    <iyz>6.66148e-06</iyz>
                    <izz>0.000178997</izz>
                </inertia>
            </inertial>
            <collision name="Body_REP_collision">
                <pose>0 -0 0 0 -0 0</pose>
                <geometry>
                    <mesh>
                        <scale>1 1 1</scale>
                        <uri>model://drchubo/meshes/Body_REP.stl</uri>
                    </mesh>
                </geometry>
            </collision>
            <visual name="Body_REP_vis">
                <pose>0 -0 0 0 -0 0</pose>
                <geometry>
                    <mesh>
                        <scale>1 1 1</scale>
                        <uri>model://drchubo/meshes/Body_REP.stl</uri>
                    </mesh>
                </geometry>
            </visual>
        </link>
        <joint type="revolute" name="REP">
            <child>Body_REP</child>
            <parent>Body_RSY</parent>
            <axis>
                <xyz>0 1 0</xyz>
                <limit>
                    <lower>-2.96</lower>
                    <upper>0</upper>
                    <effort>100</effort>
                    <velocity>10</velocity>
                </limit>
                <dynamics />
            </axis>
        </joint>
        <link name="Body_RWY">
            <pose>0.00152455 -0.208513 -0.2196 0 -0 0</pose>
            <inertial>
                <pose>4.52566e-05 -0.063616 -0.095905 0 -0 0</pose>
                <mass>0.434231</mass>
                <inertia>
                    <ixx>0.00354953</ixx>
                    <ixy>6.67149e-07</ixy>
                    <ixz>2.34545e-06</ixz>
                    <iyy>0.00320829</iyy>
                    <iyz>0.000697731</iyz>
                    <izz>0.000522002</izz>
                </inertia>
            </inertial>
            <collision name="Body_RWY_collision">
                <pose>0 -0 0 0 -0 0</pose>
                <geometry>
                    <mesh>
                        <scale>1 1 1</scale>
                        <uri>model://drchubo/meshes/Body_RWY.stl</uri>
                    </mesh>
                </geometry>
            </collision>
            <visual name="Body_RWY_vis">
                <pose>0 -0 0 0 -0 0</pose>
                <geometry>
                    <mesh>
                        <scale>1 1 1</scale>
                        <uri>model://drchubo/meshes/Body_RWY.stl</uri>
                    </mesh>
                </geometry>
            </visual>
        </link>
        <joint type="revolute" name="RWY">
            <child>Body_RWY</child>
            <parent>Body_REP</parent>
            <axis>
                <xyz>0 0 1</xyz>
                <limit>
                    <lower>-3.14</lower>
                    <upper>3.14</upper>
                    <effort>100</effort>
                    <velocity>10</velocity>
                </limit>
                <dynamics />
            </axis>
        </joint>
        <link name="Body_RWP">
            <pose>0.00152455 -0.208513 -0.40431 0 -1.5708 0</pose>
            <inertial>
                <pose>-9.30859e-05 -0.0135063 0.0305015 0 -0 0</pose>
                <mass>0.219017</mass>
                <inertia>
                    <ixx>0.000536599</ixx>
                    <ixy>1.09318e-06</ixy>
                    <ixz>6.19834e-07</ixz>
                    <iyy>0.000445109</iyy>
                    <iyz>8.97811e-05</iyz>
                    <izz>0.000148768</izz>
                </inertia>
            </inertial>
            <collision name="Body_RWP_collision">
                <pose>0 -0 0 0 -0 0</pose>
                <geometry>
                    <mesh>
                        <scale>1 1 1</scale>
                        <uri>model://drchubo/meshes/Body_RWP.stl</uri>
                    </mesh>
                </geometry>
            </collision>
            <visual name="Body_RWP_vis">
                <pose>0 -0 0 0 -0 0</pose>
                <geometry>
                    <mesh>
                        <scale>1 1 1</scale>
                        <uri>model://drchubo/meshes/Body_RWP.stl</uri>
                    </mesh>
                </geometry>
            </visual>
        </link>
        <joint type="revolute" name="RWP">
            <child>Body_RWP</child>
            <parent>Body_RWY</parent>
            <axis>
                <xyz>0 1 0</xyz>
                <limit>
                    <lower>-3.14</lower>
                    <upper>3.14</upper>
                    <effort>100</effort>
                    <velocity>10</velocity>
                </limit>
                <dynamics />
            </axis>
        </joint>
        <link name="Body_RWR">
            <pose>0.0130245 -0.208513 -0.40431 0 -1.5708 0</pose>
            <inertial>
                <pose>0.000360815 0.00215836 -0.0655917 0 -0 0</pose>
                <mass>0.269108</mass>
                <inertia>
                    <ixx>0.00115611</ixx>
                    <ixy>-5.43644e-07</ixy>
                    <ixz>-8.57165e-07</ixz>
                    <iyy>0.00110454</iyy>
                    <iyz>-5.88366e-06</iyz>
                    <izz>0.000216819</izz>
                </inertia>
            </inertial>
            <collision name="Body_RWR_collision">
                <pose>0 -0 0 0 -0 0</pose>
                <geometry>
                    <mesh>
                        <scale>1 1 1</scale>
                        <uri>model://drchubo/meshes/Body_RWR.stl</uri>
                    </mesh>
                </geometry>
            </collision>
            <visual name="Body_RWR_vis">
                <pose>0 -0 0 0 -0 0</pose>
                <geometry>
                    <mesh>
                        <scale>1 1 1</scale>
                        <uri>model://drchubo/meshes/Body_RWR.stl</uri>
                    </mesh>
                </geometry>
            </visual>
        </link>
        <joint type="revolute" name="RWR">
            <child>Body_RWR</child>
            <parent>Body_RWP</parent>
            <axis>
                <xyz>-1 0 2.22045e-16</xyz>
                <limit>
                    <lower>-3.14</lower>
                    <upper>3.14</upper>
                    <effort>100</effort>
                    <velocity>10</velocity>
                </limit>
                <dynamics />
            </axis>
        </joint>
        <link name="Body_RF1">
            <pose>0.0885245 -0.192043 -0.38131 0 -1.47552 0</pose>
            <inertial>
                <pose>0.0408954 0.0103258 -0.00671454 0 -0 0</pose>
                <mass>0.0548659</mass>
                <inertia>
                    <ixx>1.25606e-05</ixx>
                    <ixy>-1.93836e-07</ixy>
                    <ixz>-1.55634e-05</ixz>
                    <iyy>5.80752e-05</iyy>
                    <iyz>1.14011e-07</iyz>
                    <izz>4.92973e-05</izz>
                </inertia>
            </inertial>
            <collision name="Body_RF1_collision">
                <pose>0 -0 0 0 -0 0</pose>
                <geometry>
                    <mesh>
                        <scale>1 1 1</scale>
                        <uri>model://drchubo/meshes/Body_RF1.stl</uri>
                    </mesh>
                </geometry>
            </collision>
            <visual name="Body_RF1_vis">
                <pose>0 -0 0 0 -0 0</pose>
                <geometry>
                    <mesh>
                        <scale>1 1 1</scale>
                        <uri>model://drchubo/meshes/Body_RF1.stl</uri>
                    </mesh>
                </geometry>
            </visual>
        </link>
        <joint type="revolute" name="RF1">
            <child>Body_RF1</child>
            <parent>Body_RWR</parent>
            <axis>
                <xyz>0 1 0</xyz>
                <limit>
                    <lower>-0.1</lower>
                    <upper>1.1</upper>
                    <effort>100</effort>
                    <velocity>10</velocity>
                </limit>
                <dynamics />
            </axis>
        </joint>
        <link name="Body_RF2">
            <pose>0.0885245 -0.224984 -0.38131 0 -1.47552 0</pose>
            <inertial>
                <pose>0.0408954 -0.0107335 -0.00671454 0 -0 0</pose>
                <mass>0.0548659</mass>
                <inertia>
                    <ixx>1.25606e-05</ixx>
                    <ixy>-1.93836e-07</ixy>
                    <ixz>-1.55634e-05</ixz>
                    <iyy>5.80752e-05</iyy>
                    <iyz>1.14011e-07</iyz>
                    <izz>4.92973e-05</izz>
                </inertia>
            </inertial>
            <collision name="Body_RF2_collision">
                <pose>0 -0 0 0 -0 0</pose>
                <geometry>
                    <mesh>
                        <scale>1 1 1</scale>
                        <uri>model://drchubo/meshes/Body_RF2.stl</uri>
                    </mesh>
                </geometry>
            </collision>
            <visual name="Body_RF2_vis">
                <pose>0 -0 0 0 -0 0</pose>
                <geometry>
                    <mesh>
                        <scale>1 1 1</scale>
                        <uri>model://drchubo/meshes/Body_RF2.stl</uri>
                    </mesh>
                </geometry>
            </visual>
        </link>
        <joint type="revolute" name="RF2">
            <child>Body_RF2</child>
            <parent>Body_RWR</parent>
            <axis>
                <xyz>0 1 0</xyz>
                <limit>
                    <lower>-0.1</lower>
                    <upper>1.1</upper>
                    <effort>100</effort>
                    <velocity>10</velocity>
                </limit>
                <dynamics />
            </axis>
        </joint>
        <link name="Body_RF3">
            <pose>0.0885245 -0.208513 -0.42731 -3.14159 1.47552 3.38109e-14</pose>
            <inertial>
                <pose>0.0408954 -0.000203817 -0.00671454 0 -0 0</pose>
                <mass>0.0548659</mass>
                <inertia>
                    <ixx>1.25606e-05</ixx>
                    <ixy>-1.93836e-07</ixy>
                    <ixz>-1.55634e-05</ixz>
                    <iyy>5.80752e-05</iyy>
                    <iyz>1.14011e-07</iyz>
                    <izz>4.92973e-05</izz>
                </inertia>
            </inertial>
            <collision name="Body_RF3_collision">
                <pose>0 -0 0 0 -0 0</pose>
                <geometry>
                    <mesh>
                        <scale>1 1 1</scale>
                        <uri>model://drchubo/meshes/Body_RF3.stl</uri>
                    </mesh>
                </geometry>
            </collision>
            <visual name="Body_RF3_vis">
                <pose>0 -0 0 0 -0 0</pose>
                <geometry>
                    <mesh>
                        <scale>1 1 1</scale>
                        <uri>model://drchubo/meshes/Body_RF3.stl</uri>
                    </mesh>
                </geometry>
            </visual>
        </link>
        <joint type="revolute" name="RF3">
            <child>Body_RF3</child>
            <parent>Body_RWR</parent>
            <axis>
                <xyz>-4.93038e-31 -1 -3.23109e-15</xyz>
                <limit>
                    <lower>-0.1</lower>
                    <upper>1.1</upper>
                    <effort>100</effort>
                    <velocity>10</velocity>
                </limit>
                <dynamics />
            </axis>
        </joint>
    </model>
</sdf>
